/var/spool/slurmd/job00337/slurm_script: line 21: /ubsn/home/23063003r/miniconda3/etc/profile.d/conda.sh: No such file or directory
Traceback (most recent call last):
  File "/ubsnhome/23063003r/.conda/envs/refgame/lib/python3.10/site-packages/transformers/utils/hub.py", line 470, in cached_files
    hf_hub_download(
  File "/ubsnhome/23063003r/.conda/envs/refgame/lib/python3.10/site-packages/huggingface_hub/utils/_validators.py", line 106, in _inner_fn
    validate_repo_id(arg_value)
  File "/ubsnhome/23063003r/.conda/envs/refgame/lib/python3.10/site-packages/huggingface_hub/utils/_validators.py", line 154, in validate_repo_id
    raise HFValidationError(
huggingface_hub.errors.HFValidationError: Repo id must be in the form 'repo_name' or 'namespace/repo_name': '/puhome/23063003r/refgame_project/models/gpt2'. Use `repo_type` argument if needed.

During handling of the above exception, another exception occurred:

Traceback (most recent call last):
  File "/ubsn/home/23063003r/refgame_project/scripts/commu_gpt.py", line 21, in <module>
    tokenizer = AutoTokenizer.from_pretrained(MODEL_PATH)
  File "/ubsnhome/23063003r/.conda/envs/refgame/lib/python3.10/site-packages/transformers/models/auto/tokenization_auto.py", line 950, in from_pretrained
    tokenizer_config = get_tokenizer_config(pretrained_model_name_or_path, **kwargs)
  File "/ubsnhome/23063003r/.conda/envs/refgame/lib/python3.10/site-packages/transformers/models/auto/tokenization_auto.py", line 782, in get_tokenizer_config
    resolved_config_file = cached_file(
  File "/ubsnhome/23063003r/.conda/envs/refgame/lib/python3.10/site-packages/transformers/utils/hub.py", line 312, in cached_file
    file = cached_files(path_or_repo_id=path_or_repo_id, filenames=[filename], **kwargs)
  File "/ubsnhome/23063003r/.conda/envs/refgame/lib/python3.10/site-packages/transformers/utils/hub.py", line 522, in cached_files
    resolved_files = [
  File "/ubsnhome/23063003r/.conda/envs/refgame/lib/python3.10/site-packages/transformers/utils/hub.py", line 523, in <listcomp>
    _get_cache_file_to_return(path_or_repo_id, filename, cache_dir, revision) for filename in full_filenames
  File "/ubsnhome/23063003r/.conda/envs/refgame/lib/python3.10/site-packages/transformers/utils/hub.py", line 140, in _get_cache_file_to_return
    resolved_file = try_to_load_from_cache(path_or_repo_id, full_filename, cache_dir=cache_dir, revision=revision)
  File "/ubsnhome/23063003r/.conda/envs/refgame/lib/python3.10/site-packages/huggingface_hub/utils/_validators.py", line 106, in _inner_fn
    validate_repo_id(arg_value)
  File "/ubsnhome/23063003r/.conda/envs/refgame/lib/python3.10/site-packages/huggingface_hub/utils/_validators.py", line 154, in validate_repo_id
    raise HFValidationError(
huggingface_hub.errors.HFValidationError: Repo id must be in the form 'repo_name' or 'namespace/repo_name': '/puhome/23063003r/refgame_project/models/gpt2'. Use `repo_type` argument if needed.
